<?xml version="1.0"?>

<robot xmlns:xacro="http://www.ros.org/wiki/xacro">

    <xacro:include filename="$(find quake_description)/xacro/transmission.xacro"/>

    <xacro:macro name="arm" params="parent *origin">
    <joint
        name="arm_joint0"
        type="revolute">
        <xacro:insert_block name="origin"/> 
        <parent
        link="${parent}" />
        <child
        link="arm_base" />
        <axis
        xyz="1 1 1" />
        <limit
        lower="0"
        upper="0"
        effort="${arm_joint_torque_max}"
        velocity="${arm_joint_velocity_max}" />
        
    </joint>

    <link name="arm_base">
    <inertial>
      <origin
        xyz="-0.000123271228625182 -0.000457440844506329 0.0515095441005062"
        rpy="0 0 0" />
      <mass
        value="0.877911456088797" />
      <inertia
        ixx="0.00128543342731357"
        ixy="1.28958801650785E-06"
        ixz="-2.99859290547924E-08"
        iyy="0.00130158856226942"
        iyz="2.31482241641968E-06"
        izz="0.00109109189010787" />
    </inertial>
    <visual>
      <origin
        xyz="0 0 0"
        rpy="0 0 0" />
      <geometry>
        <mesh
          filename="package://quake_description/meshes/base-link.STL" />
      </geometry>
      <material
        name="gold">
      </material>
    </visual>
    <collision>
      <origin
        xyz="0 0 0"
        rpy="0 0 0" />
      <geometry>
        <mesh
          filename="package://quake_description/meshes/base-link.STL" />
      </geometry>
    </collision>
  </link>
    <joint name="arm_joint1" type="revolute">
    <origin
      xyz="0 0 0.18895"
      rpy="0 0 0" />
    <parent
      link="arm_base" />
    <child
      link="arm_link1" />
    <axis
      xyz="0 0 1" />
    <dynamics damping="${arm_damping}" friction="${arm_friction}"/>
    <limit
      lower="-6.283"
      upper="6.283"
      effort="${arm_joint_torque_max}"
      velocity="${arm_joint_velocity_max}" />
    </joint>

    <link name="arm_link1">
        <inertial>
      <origin
        xyz="-7.32977759074216E-06 -0.00791907875491554 -0.0160543423366936"
        rpy="0 0 0" />
      <mass
        value="1.34064145777001" />
      <inertia
        ixx="0.00277869400603243"
        ixy="1.38555339514813E-07"
        ixz="-1.75405148215417E-08"
        iyy="0.00186257062968088"
        iyz="0.000334478033290181"
        izz="0.0027072159945456" />
    </inertial>
    <visual>
      <origin
        xyz="0 0 0"
        rpy="0 0 0" />
      <geometry>
        <mesh
          filename="package://quake_description/meshes/link1.STL" />
      </geometry>
      <material
        name="gold">
      </material>
    </visual>
    <collision>
      <origin
        xyz="0 0 0"
        rpy="0 0 0" />
      <geometry>
        <mesh
          filename="package://quake_description/meshes/link1.STL" />
      </geometry>
    </collision>
    </link>
    <joint name="arm_joint2" type="revolute">
        <origin
      xyz="0 0 0"
      rpy="1.5708 -1.5708 0" />
    <parent
      link="arm_link1" />
    <child
      link="arm_link2" />
    <axis
      xyz="0 0 1" />
    <dynamics damping="${arm_damping}" friction="${arm_friction}"/>
    <limit
      lower="-2"
      upper="2"
      effort="${arm_joint_torque_max}"
      velocity="${arm_joint_velocity_max}" />
    </joint>

    <link name="arm_link2">
        <inertial>
      <origin
        xyz="0.185277248980488 2.21896447630265E-06 0.00336626931239081"
        rpy="0 0 0" />
      <mass
        value="1.45359715861183" />
      <inertia
        ixx="0.00191578125854147"
        ixy="1.13193471396093E-05"
        ixz="-2.19006295617759E-05"
        iyy="0.00258221313887042"
        iyz="-1.08816868505818E-08"
        izz="0.00231364206381302" />
    </inertial>
    <visual>
      <origin
        xyz="0 0 0"
        rpy="0 0 0" />
      <geometry>
        <mesh
          filename="package://quake_description/meshes/link2.STL" />
      </geometry>
      <material
        name="gold">
      </material>
    </visual>
    <collision>
      <origin
        xyz="0 0 0"
        rpy="0 0 0" />
      <geometry>
        <mesh
          filename="package://quake_description/meshes/link2.STL" />
      </geometry>
    </collision>
    </link>

    <joint name="arm_joint3" type="revolute">
        <origin
      xyz="0.27 0 0"
      rpy="0 0 -1.5708" />
    <parent
      link="arm_link2" />
    <child
      link="arm_link3" />
    <axis
      xyz="0 0 1" />
    <dynamics damping="${arm_damping}" friction="${arm_friction}"/>
    <limit
      lower="-0.959"
      upper="3.141"
      effort="${arm_joint_torque_max}"
      velocity="${arm_joint_velocity_max}" />
    </joint>

    <link name="arm_link3">
        <inertial>
      <origin
        xyz="0.073115206029098 0.0786992715692952 0.0238400616254055"
        rpy="0 0 0" />
      <mass
        value="0.811044855619832" />
      <inertia
        ixx="0.0010083225197341"
        ixy="-0.0001579111959342"
        ixz="0.0001061099141487"
        iyy="0.000761094203658772"
        iyz="6.04442595931848E-05"
        izz="0.00112454610525827" />
    </inertial>
    <visual>
      <origin
        xyz="0 0 0"
        rpy="0 0 0" />
      <geometry>
        <mesh
          filename="package://quake_description/meshes/link3.STL" />
      </geometry>
      <material
        name="gold">
      </material>
    </visual>
    <collision>
      <origin
        xyz="0 0 0"
        rpy="0 0 0" />
      <geometry>
        <mesh
          filename="package://quake_description/meshes/link3.STL" />
      </geometry>
    </collision>
    </link>
    <joint name="arm_joint4" type="revolute">
        <origin
      xyz="0.10132 0.379 0"
      rpy="-1.5708 0 0" />
    <parent
      link="arm_link3" />
    <child
      link="arm_link4" />
    <axis
      xyz="0 0 1" />
    <dynamics damping="${arm_damping}" friction="${arm_friction}"/>
    <limit
      lower="-6.283"
      upper="6.283"
      effort="${arm_joint_torque_max}"
      velocity="${arm_joint_velocity_max}" />
    </joint>

    <link name="arm_link4">
        <inertial>
      <origin
        xyz="9.76592164701612E-05 0.0120516706236454 -0.048529176267373"
        rpy="0 0 0" />
      <mass
        value="0.666261265083931" />
      <inertia
        ixx="0.00100494577336089"
        ixy="1.27652261688004E-06"
        ixz="-7.67850578981086E-07"
        iyy="0.00090331467386807"
        iyz="-5.99168725952912E-05"
        izz="0.000545247441255972" />
    </inertial>
    <visual>
      <origin
        xyz="0 0 0"
        rpy="0 0 0" />
      <geometry>
        <mesh
          filename="package://quake_description/meshes/link4.STL" />
      </geometry>
      <material
        name="gold">
      </material>
    </visual>
    <collision>
      <origin
        xyz="0 0 0"
        rpy="0 0 0" />
      <geometry>
        <mesh
          filename="package://quake_description/meshes/link4.STL" />
      </geometry>
    </collision>
    </link>
    <joint name="arm_joint5" type="revolute">
        <origin
      xyz="0 0 0"
      rpy="1.5708 0 0" />
    <parent
      link="arm_link4" />
    <child
      link="arm_link5" />
    <axis
      xyz="0 0 1" />
    <dynamics damping="${arm_damping}" friction="${arm_friction}"/>
    <limit
      lower="-1.657"
      upper="1.657"
      effort="${arm_joint_torque_max}"
      velocity="${arm_joint_velocity_max}" />
    </joint>

    <link name="arm_link5">
        <inertial>
      <origin
        xyz="5.27556976771676E-05 0.0923357076323008 -0.0360041600868995"
        rpy="0 0 0" />
      <mass
        value="0.719099123102519" />
      <inertia
        ixx="0.000909912397615781"
        ixy="9.42160904768399E-07"
        ixz="-1.39084474203557E-06"
        iyy="0.000379079147054095"
        iyz="-8.77200994395369E-05"
        izz="0.000860136435038053" />
    </inertial>
    <visual>
      <origin
        xyz="0 0 0"
        rpy="0 0 0" />
      <geometry>
        <mesh
          filename="package://quake_description/meshes/link5.STL" />
      </geometry>
      <material
        name="gold">
      </material>
    </visual>
    <collision>
      <origin
        xyz="0 0 0"
        rpy="0 0 0" />
      <geometry>
        <mesh
          filename="package://quake_description/meshes/link5.STL" />
      </geometry>
    </collision>
    </link>
    <joint name="arm_joint6" type="revolute">
        <origin
      xyz="0 0.1745 0"
      rpy="-1.5708 0 0" />
    <parent
      link="arm_link5" />
    <child
      link="arm_link6" />
    <axis
      xyz="0 0 1" />
    <dynamics damping="${arm_damping}" friction="${arm_friction}"/>
    <limit
      lower="-6.283"
      upper="6.283"
      effort="${arm_joint_torque_max}"
      velocity="${arm_joint_velocity_max}" />
    </joint>

    <link name="arm_link6">
        <inertial>
      <origin
        xyz="0.00172505025135854 0.00147107012245623 0.0754001344633501"
        rpy="0 0 0" />
      <mass
        value="0.891422492606671" />
      <inertia
        ixx="0.000629768812000687"
        ixy="1.31260928861912E-06"
        ixz="-6.70010340750907E-07"
        iyy="0.000867311719247634"
        iyz="-6.68397220849477E-05"
        izz="0.00082870557314601" />
    </inertial>
    <visual>
      <origin
        xyz="0 0 0"
        rpy="0 0 0" />
      <geometry>
        <mesh
          filename="package://quake_description/meshes/link6.STL" />
      </geometry>
      <material
        name="gold">
      </material>
    </visual>
    <collision>
      <origin
        xyz="0 0 0"
        rpy="0 0 0" />
      <geometry>
        <mesh
          filename="package://quake_description/meshes/link6.STL" />
      </geometry>
    </collision>
    </link>
  </xacro:macro>
  <xacro:arm_transmission/>

</robot>
