    <link
    name="link1">
    <inertial>
      <origin
        xyz="3.46944695195361E-18 -1.38777878078145E-16 0.0"   
        rpy="0 0 0" />
      <mass
        value="0.193099757292959" />
      <inertia
        ixx="0.00056685265690625"
        ixy="-2.29216651183795E-06"
        ixz="3.16497851999031E-20"
        iyy="0.000498050922452996"
        iyz="-1.67164018957342E-20"
        izz="0.000477248477063315" />
    </inertial>
    <visual>
      <origin
        xyz="0 0 0"
        rpy="0 0 0" />
      <geometry>
        <mesh
          filename="package://arm-urdf/meshes/link1.STL" />
      </geometry>
      <material
        name="">
        <color
          rgba="0.792156862745098 0.819607843137255 0.933333333333333 1" />
      </material>
    </visual>
    <collision>
      <origin
        xyz="0 0 0"
        rpy="0 0 0" />
      <geometry>
        <mesh
          filename="package://arm-urdf/meshes/link1.STL" />
      </geometry>
    </collision>
  </link>
  <joint
    name="joint1"
    type="revolute">
    <!-- <origin
      xyz="0 0 0.11702" 
      rpy="0 0 0" /> -->
    <origin
      xyz="0. 0 0.1" 
      rpy="0 0 0" />
    <parent
      link="base_link" />
    <child
      link="link1" />
    <axis
      xyz="0 0 1" />
    <limit
      lower="-3.14"
      upper="3.14"
      effort="0"
      velocity="0" />
  </joint>
  <link
    name="link2">
    <inertial>
      <origin
        xyz="-0.146649573591894 0.00956316610568711 0.0011010646321849"
        rpy="0 0 0" />
      <mass
        value="3.19284447984026" />
      <inertia
        ixx="0.00477436455517655"
        ixy="4.71225224795049E-05"
        ixz="-1.23167153938677E-06"
        iyy="0.00549402862561509"
        iyz="7.27080160651822E-07"
        izz="0.00332799645961968" />
    </inertial>
    <visual>
      <origin
        xyz="0 0 0"
        rpy="0 0 0" />
      <geometry>
        <mesh
          filename="package://arm-urdf/meshes/link2.STL" />
      </geometry>
      <material
        name="">
        <color
          rgba="0.898039215686275 0.917647058823529 0.929411764705882 1" />
      </material>
    </visual>
    <collision>
      <origin
        xyz="0 0 0"
        rpy="0 0 0" />
      <geometry>
        <mesh
          filename="package://arm-urdf/meshes/link2.STL" />
      </geometry>
    </collision>
  </link>
  <joint
    name="joint2"
    type="revolute">
    <origin
      xyz="0 0 0.06545"
      rpy="1.5708 0 -0.033266" />
    <parent
      link="link1" />
    <child
      link="link2" />
    <axis
      xyz="0 0 -1" />
    <limit
      lower="-3.14"
      upper="3.14"
      effort="0"
      velocity="0" />
  </joint>
  <link
    name="link3">
    <inertial>
      <origin
        xyz="0.100660682762928 0.0799366434801956 -3.27958979917664E-07"
        rpy="0 0 0" />
      <mass
        value="1.16224390586324" />
      <inertia
        ixx="0.000805796549158119"
        ixy="-0.000100608451948743"
        ixz="1.31186372237748E-09"
        iyy="0.00173648327024609"
        iyz="-2.03317230316018E-09"
        izz="0.00192848887316203" />
    </inertial>
    <visual>
      <origin
        xyz="0 0 0"
        rpy="0 0 0" />
      <geometry>
        <mesh
          filename="package://arm-urdf/meshes/link3.STL" />
      </geometry>
      <material
        name="">
        <color
          rgba="1 1 1 1" />
      </material>
    </visual>
    <collision>
      <origin
        xyz="0 0 0"
        rpy="0 0 0" />
      <geometry>
        <mesh
          filename="package://arm-urdf/meshes/link3.STL" />
      </geometry>
    </collision>
  </link>
  <joint
    name="joint3"
    type="revolute">
    <origin
      xyz="-0.324311314585255 0.0211464236944281 0.0026999994296879"
      rpy="0.000648587514617684 -4.22800042326571E-05 -2.1611534375014E-05" />
    <parent
      link="link2" />
    <child
      link="link3" />
    <axis
      xyz="0 0 1" />
    <limit
      lower="-3.14"
      upper="3.14"
      effort="0"
      velocity="0" />
  </joint>
  <link
    name="link4">
    <inertial>
      <origin
        xyz="0.00886992770836434 -0.00555506871374395 0.178344624200317"
        rpy="0 0 0" />
      <mass
        value="1.0220767804968" />
      <inertia
        ixx="0.000860327598577306"
        ixy="0.000262875743030854"
        ixz="-1.81814346555289E-06"
        iyy="0.0011154350672221"
        iyz="1.13985384990976E-06"
        izz="0.0011239781014809" />
    </inertial>
    <visual>
      <origin
        xyz="0 0 0"
        rpy="0 0 0" />
      <geometry>
        <mesh
          filename="package://arm-urdf/meshes/link4.STL" />
      </geometry>
      <material
        name="">
        <color
          rgba="1 1 1 1" />
      </material>
    </visual>
    <collision>
      <origin
        xyz="0 0 0"
        rpy="0 0 0" />
      <geometry>
        <mesh
          filename="package://arm-urdf/meshes/link4.STL" />
      </geometry>
    </collision>
  </link>
  <joint
    name="joint4"
    type="revolute">
    <origin
      xyz="0.18614 0.0916 0"
      rpy="1.5708 1.0144 1.5501" />
    <parent
      link="link3" />
    <child
      link="link4" />
    <axis
      xyz="0 0 1" />
    <limit
      lower="-3.14"
      upper="3.14"
      effort="0"
      velocity="0" />
  </joint>
  <link
    name="link5">
    <inertial>
      <origin
        xyz="0.0914207748667139 -0.00448046436657312 -0.00659273076223413"
        rpy="0 0 0" />
      <mass
        value="1.004792848152" />
      <inertia
        ixx="0.000731421128281677"
        ixy="5.01187682802808E-05"
        ixz="-0.000269598428744111"
        iyy="0.00175161184674713"
        iyz="1.32123857867735E-05"
        izz="0.00155291030457456" />
    </inertial>
    <visual>
      <origin
        xyz="0 0 0"
        rpy="0 0 0" />
      <geometry>
        <mesh
          filename="package://arm-urdf/meshes/link5.STL" />
      </geometry>
      <material
        name="">
        <color
          rgba="1 1 1 1" />
      </material>
    </visual>
    <collision>
      <origin
        xyz="0 0 0"
        rpy="0 0 0" />
      <geometry>
        <mesh
          filename="package://arm-urdf/meshes/link5.STL" />
      </geometry>
    </collision>
  </link>
  <joint
    name="joint5"
    type="revolute">
    <origin
      xyz="-0.0056783 0.0035562 0.198"
      rpy="-1.5708 -1.55 1.0113" />
    <parent
      link="link4" />
    <child
      link="link5" />
    <axis
      xyz="0 0 1" />
    <limit
      lower="-2.09"
      upper="2.09"
      effort="0"
      velocity="0" />
  </joint>
  <link
    name="link6">
    <inertial>
      <origin
        xyz="-0.0099246413085432 -0.00775117193465141 0.0647439008055309"
        rpy="0 0 0" />
      <mass
        value="0.447480614333938" />
      <inertia
        ixx="0.00065469061783035"
        ixy="7.19439187620376E-05"
        ixz="9.65923414024793E-06"
        iyy="0.000620705064006462"
        iyz="7.67444771574053E-06"
        izz="0.000486109926710592" />
    </inertial>
    <visual>
      <origin
        xyz="0 0 0"
        rpy="0 0 0" />
      <geometry>
        <mesh
          filename="package://arm-urdf/meshes/link6.STL" />
      </geometry>
      <material
        name="">
        <color
          rgba="1 1 1 1" />
      </material>
    </visual>
    <collision>
      <origin
        xyz="0 0 0"
        rpy="0 0 0" />
      <geometry>
        <mesh
          filename="package://arm-urdf/meshes/link6.STL" />
      </geometry>
    </collision>
  </link>
  <joint
    name="joint6"
    type="revolute">
    <origin
      xyz="0.15941 -0.0078124 0"
      rpy="1.5708 0.59676 1.5218" />
    <parent
      link="link5" />
    <child
      link="link6" />
    <axis
      xyz="0 0 -1" />
    <limit
      lower="-3.14"
      upper="3.14"
      effort="0"
      velocity="0" />
  </joint>