<?xml version="1.0" encoding="utf-8"?>
<!-- =================================================================================== -->
<!-- |    This document was autogenerated by xacro from robot.xacro                    | -->
<!-- |    EDITING THIS FILE BY HAND IS NOT RECOMMENDED                                 | -->
<!-- =================================================================================== -->
<robot name="quake_description">
  <!-- ? -->
  <!-- ? -->
  <!-- arm -->
  <!-- <xacro:property name="arm_base_mass" value=""/> 
    <xacro:property name="arm_base_width" value=""/> 
    <xacro:property name="arm_base_length" value=""/> 
    <xacro:property name="arm_base_height" value=""/> 
    <xacro:property name="arm_base_com_x" value=""/> 
    <xacro:property name="arm_base_com_y" value=""/> 
    <xacro:property name="arm_base_com_z" value=""/> 
    <xacro:property name="arm_base_ixx" value=""/>
    <xacro:property name="arm_base_ixy" value=""/>
    <xacro:property name="arm_base_ixz" value=""/>
    <xacro:property name="arm_base_iyy" value=""/>
    <xacro:property name="arm_base_iyz" value=""/>
    <xacro:property name="arm_base_izz" value=""/> -->
  <material name="black">
    <color rgba="0.0 0.0 0.0 1.0"/>
  </material>
  <material name="blue">
    <color rgba="0.0 0.0 0.8 1.0"/>
  </material>
  <material name="green">
    <color rgba="0.0 0.8 0.0 1.0"/>
  </material>
  <material name="grey">
    <color rgba="0.2 0.2 0.2 1.0"/>
  </material>
  <material name="silver">
    <color rgba="0.913725490196 0.913725490196 0.847058823529 1.0"/>
  </material>
  <material name="gold">
    <color rgba="1.0 0.843137254902 0.0 1.0"/>
  </material>
  <material name="orange">
    <color rgba="1.0 0.423529411765 0.0392156862745 1.0"/>
  </material>
  <material name="brown">
    <color rgba="0.870588235294 0.811764705882 0.764705882353 1.0"/>
  </material>
  <material name="red">
    <color rgba="0.8 0.0 0.0 1.0"/>
  </material>
  <material name="white">
    <color rgba="1.0 1.0 1.0 1.0"/>
  </material>
  <!-- ros_control plugin -->
 

    <link name="base">
        <visual>
            <origin rpy="0 0 0" xyz="0 0 0"/>
            <geometry>
                <box size="0.001 0.001 0.001"/>
            </geometry>
        </visual>
    </link>

    <joint name="floating_base" type="fixed">
        <origin rpy="0 0 0" xyz="0.1 0.1 0"/>
        <parent link="base"/>
        <child link="trunk"/>
    </joint> 
  <link name="trunk">
    <visual>
      <origin rpy="0 0 0" xyz="0 0 0"/>
      <geometry>
        <mesh filename="package://quake_description/meshes/trunk.STL" scale="1 1 1"/>
      </geometry>
      <material name="gold"/>
    </visual>
    <!-- <collision>
            <origin rpy="0 0 0" xyz="0 0 0"/>
            <geometry>
                <mesh filename="package://quake_description/meshes/trunk.STL" scale="1 1 1"/>
            </geometry>
        </collision> -->
    <inertial>
      <origin rpy="0 0 0" xyz="0.0 0.0 0.0"/>
      <mass value="30.116"/>
      <inertia ixx="0.2" ixy="-0.00023853" ixz="2.4844e-05" iyy="0.5" iyz="-0.00044715" izz="0.6"/>
    </inertial>
  </link>
  <joint name="imu_joint" type="fixed">
    <parent link="trunk"/>
    <child link="imu_link"/>
    <origin rpy="0 0 0" xyz="0 0 0"/>
  </joint>
  <link name="imu_link">
    <inertial>
      <mass value="0.001"/>
      <origin rpy="0 0 0" xyz="0 0 0"/>
      <inertia ixx="0.0001" ixy="0" ixz="0" iyy="0.000001" iyz="0" izz="0.0001"/>
    </inertial>
    <visual>
      <origin rpy="0 0 0" xyz="0 0 0"/>
      <geometry>
        <box size="0.001 0.001 0.001"/>
      </geometry>
      <material name="red"/>
    </visual>
    <collision>
      <origin rpy="0 0 0" xyz="0 0 0"/>
      <geometry>
        <box size=".001 .001 .001"/>
      </geometry>
    </collision>
  </link>
  <joint name="FR_hip_joint" type="revolute">
    <origin rpy="0 0 0" xyz="0.241 -0.095 0"/>
    <parent link="trunk"/>
    <child link="FR_hip"/>
    <axis xyz="1 0 0"/>
    <dynamics damping="0.4" friction="0.2"/>
    <limit effort="200" lower="-1.13008323737" upper="1.13008323737" velocity="52.4"/>
  </joint>
  <link name="FR_hip">
    <visual>
      <origin rpy="3.14159265359 0 0" xyz="0 0 0"/>
      <geometry>
        <mesh filename="package://quake_description/meshes/hip.STL" scale="1 1 1"/>
      </geometry>
      <material name="gold"/>
    </visual>
    <collision>
      <origin rpy="1.57079632679 0 0" xyz="0 0.04 0"/>
      <geometry>
        <cylinder length="0.08" radius="0.041"/>
      </geometry>
    </collision>
    <inertial>
      <origin rpy="0 0 0" xyz="-0.001568 0.008134 0.000864"/>
      <mass value="2.354"/>
      <inertia ixx="0.0047303" ixy="-2.3798e-05" ixz="-4.2348e-08" iyy="0.0051123" iyz="3.807e-06" izz="0.0035171"/>
    </inertial>
  </link>
  <joint name="FR_hip_fixed" type="fixed">
    <origin rpy="0 0 0" xyz="0 -0.04 0"/>
    <parent link="FR_hip"/>
    <child link="FR_thigh_shoulder"/>
  </joint>
  <!-- this link is only for collision -->
  <link name="FR_thigh_shoulder">
    <collision>
      <origin rpy="1.57079632679 0 0" xyz="0 0 0"/>
      <geometry>
        <cylinder length="0.08" radius="0.044"/>
      </geometry>
    </collision>
  </link>
  <joint name="FR_thigh_joint" type="revolute">
    <origin rpy="0 0 0" xyz="0.1065 -0.062 0"/>
    <parent link="FR_hip"/>
    <child link="FR_thigh"/>
    <axis xyz="0 1 0"/>
    <dynamics damping="0.4" friction="0.2"/>
    <limit effort="550" lower="-3.40025044874" upper="4.30014732279" velocity="28.6"/>
  </joint>
  <link name="FR_thigh">
    <visual>
      <origin rpy="0 0 0" xyz="0 0 0"/>
      <geometry>
        <mesh filename="package://quake_description/meshes/thigh_mirror.STL" scale="1 1 1"/>
      </geometry>
      <material name="gold"/>
    </visual>
    <collision>
      <origin rpy="0 1.57079632679 0" xyz="0 0 -0.18"/>
      <geometry>
        <box size="0.36 0.034 0.043"/>
      </geometry>
    </collision>
    <inertial>
      <origin rpy="0 0 0" xyz="-0.000482 -0.02001 -0.031996"/>
      <mass value="4.199"/>
      <inertia ixx="0.010387" ixy="-2.7648e-05" ixz="-0.0006887" iyy="0.013004" iyz="-0.00021997" izz="0.0029272"/>
    </inertial>
  </link>
  <joint name="FR_calf_joint" type="revolute">
    <origin rpy="0 0 0" xyz="0 -0.062 -0.36"/>
    <parent link="FR_thigh"/>
    <child link="FR_calf"/>
    <axis xyz="0 1 0"/>
    <dynamics damping="0.4" friction="1.0"/>
    <limit effort="550" lower="-2.900007366139" upper="-1.10021361804" velocity="28.6"/>
  </joint>
  <link name="FR_calf">
    <visual>
      <origin rpy="0 0 0" xyz="0 0 0"/>
      <geometry>
        <mesh filename="package://quake_description/meshes/calf.STL" scale="1 1 1"/>
      </geometry>
      <surface>
        <friction>
          <ode>
            <mu>100.0</mu>
            <mu2>100.0</mu2>
          </ode>
        </friction>
      </surface>
      <material name="black"/>
    </visual>
    <collision>
      <origin rpy="0 1.57079632679 0" xyz="0 0 -0.18"/>
      <geometry>
        <box size="0.36 0.016 0.016"/>
      </geometry>
      <surface>
        <friction>
          <ode>
            <mu>100.0</mu>
            <mu2>100.0</mu2>
          </ode>
        </friction>
      </surface>
    </collision>
    <inertial>
      <origin rpy="0 0 0" xyz="-0.002196 -0.000381 -0.12338"/>
      <mass value="0.593"/>
      <inertia ixx="0.0031787" ixy="-1.5425e-07" ixz="0.0002511" iyy="0.0032683" iyz="3.2937e-07" izz="0.0001467"/>
    </inertial>
  </link>
  <joint name="FR_foot_fixed" type="fixed">
    <origin rpy="0 0 0" xyz="0 0 -0.36"/>
    <parent link="FR_calf"/>
    <child link="FR_foot"/>
  </joint>
  <link name="FR_foot">
    <visual>
      <origin rpy="0 0 0" xyz="0 0 0"/>
      <geometry>
        <sphere radius="0.032"/>
      </geometry>
      <surface>
        <friction>
          <ode>
            <mu>100.0</mu>
            <mu2>100.0</mu2>
          </ode>
        </friction>
      </surface>
      <material name="black"/>
    </visual>
    <collision>
      <origin rpy="0 0 0" xyz="0 0 0"/>
      <geometry>
        <sphere radius="0.042"/>
      </geometry>
      <surface>
        <friction>
          <ode>
            <mu>100.0</mu>
            <mu2>100.0</mu2>
          </ode>
        </friction>
        <!-- <contact>
                <min_depth>0.01</min_depth>
                </contact> -->
      </surface>
    </collision>
    <inertial>
      <mass value="0.06"/>
      <inertia ixx="4.2336e-05" ixy="0.0" ixz="0.0" iyy="4.2336e-05" iyz="0.0" izz="4.2336e-05"/>
    </inertial>
  </link>
  <!-- <joint name="${name}_empty_fixed" type="fixed">
            <origin rpy="0 0 0" xyz="0 0 ${-(calf_length)}"/>
            <parent link="${name}_foot"/>
            <child link="${name}_empty"/>
        </joint>

        <link name="${name}_empty">
            <visual>
                <origin rpy="0 0 0" xyz="0 0 0"/>
                <geometry>
                    <sphere radius="0.0001"/>
                </geometry>
                <surface>
                <friction>
                <ode>
                    <mu>100.0</mu>
                    <mu2>100.0</mu2>
                </ode>
                </friction>
                </surface>
                <material name="orange"/>
            </visual>
            <collision>
                <origin rpy="0 0 0" xyz="0 0 0"/>
                <geometry>
                    <sphere radius="0.0001"/>
                </geometry>
                <surface>
                <friction>
                <ode>
                    <mu>100.0</mu>
                    <mu2>100.0</mu2>
                </ode>
                </friction>
                </surface>
            </collision>
            <inertial>
                <mass value="0"/>
                <inertia
                    ixx="0" ixy="0.0" ixz="0.0"
                    iyy="0" iyz="0.0"
                    izz="0"/>             
            </inertial>
        </link> -->
  <gazebo>
    <plugin filename="libgazebo_ros_p3d.so" name="p3d_base_controller">
      <alwaysOn>true</alwaysOn>
      <updateRate>200.0</updateRate>
      <bodyName>FR_calf</bodyName>
      <topicName>ground_truth/state/FR_foot</topicName>
      <gaussianNoise>0.0</gaussianNoise>
      <frameName>world</frameName>
      <xyzOffsets>0 0 0</xyzOffsets>
      <rpyOffsets>0 0 0</rpyOffsets>
    </plugin>
  </gazebo>
  <transmission name="FR_hip_tran">
    <type>transmission_interface/SimpleTransmission</type>
    <joint name="FR_hip_joint">
      <hardwareInterface>hardware_interface/EffortJointInterface</hardwareInterface>
    </joint>
    <actuator name="FR_hip_motor">
      <hardwareInterface>hardware_interface/EffortJointInterface</hardwareInterface>
      <mechanicalReduction>1</mechanicalReduction>
    </actuator>
  </transmission>
  <transmission name="FR_thigh_tran">
    <type>transmission_interface/SimpleTransmission</type>
    <joint name="FR_thigh_joint">
      <hardwareInterface>hardware_interface/EffortJointInterface</hardwareInterface>
    </joint>
    <actuator name="FR_thigh_motor">
      <hardwareInterface>hardware_interface/EffortJointInterface</hardwareInterface>
      <mechanicalReduction>1</mechanicalReduction>
    </actuator>
  </transmission>
  <transmission name="FR_calf_tran">
    <type>transmission_interface/SimpleTransmission</type>
    <joint name="FR_calf_joint">
      <hardwareInterface>hardware_interface/EffortJointInterface</hardwareInterface>
    </joint>
    <actuator name="FR_calf_motor">
      <hardwareInterface>hardware_interface/EffortJointInterface</hardwareInterface>
      <mechanicalReduction>1</mechanicalReduction>
    </actuator>
  </transmission>
  <joint name="FL_hip_joint" type="revolute">
    <origin rpy="0 0 0" xyz="0.241 0.095 0"/>
    <parent link="trunk"/>
    <child link="FL_hip"/>
    <axis xyz="1 0 0"/>
    <dynamics damping="0.4" friction="0.2"/>
    <limit effort="200" lower="-1.13008323737" upper="1.13008323737" velocity="52.4"/>
  </joint>
  <link name="FL_hip">
    <visual>
      <origin rpy="0 0 0" xyz="0 0 0"/>
      <geometry>
        <mesh filename="package://quake_description/meshes/hip.STL" scale="1 1 1"/>
      </geometry>
      <material name="gold"/>
    </visual>
    <collision>
      <origin rpy="1.57079632679 0 0" xyz="0 -0.04 0"/>
      <geometry>
        <cylinder length="0.08" radius="0.041"/>
      </geometry>
    </collision>
    <inertial>
      <origin rpy="0 0 0" xyz="-0.001568 -0.008134 0.000864"/>
      <mass value="2.354"/>
      <inertia ixx="0.0047303" ixy="2.3798e-05" ixz="-4.2348e-08" iyy="0.0051123" iyz="-3.807e-06" izz="0.0035171"/>
    </inertial>
  </link>
  <joint name="FL_hip_fixed" type="fixed">
    <origin rpy="0 0 0" xyz="0 0.04 0"/>
    <parent link="FL_hip"/>
    <child link="FL_thigh_shoulder"/>
  </joint>
  <!-- this link is only for collision -->
  <link name="FL_thigh_shoulder">
    <collision>
      <origin rpy="1.57079632679 0 0" xyz="0 0 0"/>
      <geometry>
        <cylinder length="0.08" radius="0.044"/>
      </geometry>
    </collision>
  </link>
  <joint name="FL_thigh_joint" type="revolute">
    <origin rpy="0 0 0" xyz="0.1065 0.062 0"/>
    <parent link="FL_hip"/>
    <child link="FL_thigh"/>
    <axis xyz="0 1 0"/>
    <dynamics damping="0.4" friction="0.2"/>
    <limit effort="550" lower="-3.40025044874" upper="4.300014732279" velocity="28.6"/>
  </joint>
  <link name="FL_thigh">
    <visual>
      <origin rpy="0 0 0" xyz="0 0 0"/>
      <geometry>
        <mesh filename="package://quake_description/meshes/thigh.STL" scale="1 1 1"/>
      </geometry>
      <material name="gold"/>
    </visual>
    <collision>
      <origin rpy="0 1.57079632679 0" xyz="0 0 -0.18"/>
      <geometry>
        <box size="0.36 0.034 0.043"/>
      </geometry>
    </collision>
    <inertial>
      <origin rpy="0 0 0" xyz="-0.000482 0.02001 -0.031996"/>
      <mass value="4.199"/>
      <inertia ixx="0.010387" ixy="2.7648e-05" ixz="-0.0006887" iyy="0.013004" iyz="0.00021997" izz="0.0029272"/>
    </inertial>
  </link>
  <joint name="FL_calf_joint" type="revolute">
    <origin rpy="0 0 0" xyz="0 0.062 -0.36"/>
    <parent link="FL_thigh"/>
    <child link="FL_calf"/>
    <axis xyz="0 1 0"/>
    <dynamics damping="0.4" friction="1.0"/>
    <limit effort="550" lower="-2.900007366139" upper="-1.10021361804" velocity="28.6"/>
  </joint>
  <link name="FL_calf">
    <visual>
      <origin rpy="0 0 0" xyz="0 0 0"/>
      <geometry>
        <mesh filename="package://quake_description/meshes/calf.STL" scale="1 1 1"/>
      </geometry>
      <surface>
        <friction>
          <ode>
            <mu>100.0</mu>
            <mu2>100.0</mu2>
          </ode>
        </friction>
      </surface>
      <material name="black"/>
    </visual>
    <collision>
      <origin rpy="0 1.57079632679 0" xyz="0 0 -0.18"/>
      <geometry>
        <box size="0.36 0.016 0.016"/>
      </geometry>
      <surface>
        <friction>
          <ode>
            <mu>100.0</mu>
            <mu2>100.0</mu2>
          </ode>
        </friction>
      </surface>
    </collision>
    <inertial>
      <origin rpy="0 0 0" xyz="-0.002196 -0.000381 -0.12338"/>
      <mass value="0.593"/>
      <inertia ixx="0.0031787" ixy="-1.5425e-07" ixz="0.0002511" iyy="0.0032683" iyz="3.2937e-07" izz="0.0001467"/>
    </inertial>
  </link>
  <joint name="FL_foot_fixed" type="fixed">
    <origin rpy="0 0 0" xyz="0 0 -0.36"/>
    <parent link="FL_calf"/>
    <child link="FL_foot"/>
  </joint>
  <link name="FL_foot">
    <visual>
      <origin rpy="0 0 0" xyz="0 0 0"/>
      <geometry>
        <sphere radius="0.032"/>
      </geometry>
      <surface>
        <friction>
          <ode>
            <mu>100.0</mu>
            <mu2>100.0</mu2>
          </ode>
        </friction>
      </surface>
      <material name="black"/>
    </visual>
    <collision>
      <origin rpy="0 0 0" xyz="0 0 0"/>
      <geometry>
        <sphere radius="0.042"/>
      </geometry>
      <surface>
        <friction>
          <ode>
            <mu>100.0</mu>
            <mu2>100.0</mu2>
          </ode>
        </friction>
        <!-- <contact>
                <min_depth>0.01</min_depth>
                </contact> -->
      </surface>
    </collision>
    <inertial>
      <mass value="0.06"/>
      <inertia ixx="4.2336e-05" ixy="0.0" ixz="0.0" iyy="4.2336e-05" iyz="0.0" izz="4.2336e-05"/>
    </inertial>
  </link>
  <!-- <joint name="${name}_empty_fixed" type="fixed">
            <origin rpy="0 0 0" xyz="0 0 ${-(calf_length)}"/>
            <parent link="${name}_foot"/>
            <child link="${name}_empty"/>
        </joint>

        <link name="${name}_empty">
            <visual>
                <origin rpy="0 0 0" xyz="0 0 0"/>
                <geometry>
                    <sphere radius="0.0001"/>
                </geometry>
                <surface>
                <friction>
                <ode>
                    <mu>100.0</mu>
                    <mu2>100.0</mu2>
                </ode>
                </friction>
                </surface>
                <material name="orange"/>
            </visual>
            <collision>
                <origin rpy="0 0 0" xyz="0 0 0"/>
                <geometry>
                    <sphere radius="0.0001"/>
                </geometry>
                <surface>
                <friction>
                <ode>
                    <mu>100.0</mu>
                    <mu2>100.0</mu2>
                </ode>
                </friction>
                </surface>
            </collision>
            <inertial>
                <mass value="0"/>
                <inertia
                    ixx="0" ixy="0.0" ixz="0.0"
                    iyy="0" iyz="0.0"
                    izz="0"/>             
            </inertial>
        </link> -->
  <gazebo>
    <plugin filename="libgazebo_ros_p3d.so" name="p3d_base_controller">
      <alwaysOn>true</alwaysOn>
      <updateRate>200.0</updateRate>
      <bodyName>FL_calf</bodyName>
      <topicName>ground_truth/state/FL_foot</topicName>
      <gaussianNoise>0.0</gaussianNoise>
      <frameName>world</frameName>
      <xyzOffsets>0 0 0</xyzOffsets>
      <rpyOffsets>0 0 0</rpyOffsets>
    </plugin>
  </gazebo>
  <transmission name="FL_hip_tran">
    <type>transmission_interface/SimpleTransmission</type>
    <joint name="FL_hip_joint">
      <hardwareInterface>hardware_interface/EffortJointInterface</hardwareInterface>
    </joint>
    <actuator name="FL_hip_motor">
      <hardwareInterface>hardware_interface/EffortJointInterface</hardwareInterface>
      <mechanicalReduction>1</mechanicalReduction>
    </actuator>
  </transmission>
  <transmission name="FL_thigh_tran">
    <type>transmission_interface/SimpleTransmission</type>
    <joint name="FL_thigh_joint">
      <hardwareInterface>hardware_interface/EffortJointInterface</hardwareInterface>
    </joint>
    <actuator name="FL_thigh_motor">
      <hardwareInterface>hardware_interface/EffortJointInterface</hardwareInterface>
      <mechanicalReduction>1</mechanicalReduction>
    </actuator>
  </transmission>
  <transmission name="FL_calf_tran">
    <type>transmission_interface/SimpleTransmission</type>
    <joint name="FL_calf_joint">
      <hardwareInterface>hardware_interface/EffortJointInterface</hardwareInterface>
    </joint>
    <actuator name="FL_calf_motor">
      <hardwareInterface>hardware_interface/EffortJointInterface</hardwareInterface>
      <mechanicalReduction>1</mechanicalReduction>
    </actuator>
  </transmission>
  <joint name="RR_hip_joint" type="revolute">
    <origin rpy="0 0 0" xyz="-0.241 -0.095 0"/>
    <parent link="trunk"/>
    <child link="RR_hip"/>
    <axis xyz="1 0 0"/>
    <dynamics damping="0.4" friction="0.2"/>
    <limit effort="200" lower="-1.13008323737" upper="1.13008323737" velocity="52.4"/>
  </joint>
  <link name="RR_hip">
    <visual>
      <origin rpy="3.14159265359 3.14159265359 0" xyz="0 0 0"/>
      <geometry>
        <mesh filename="package://quake_description/meshes/hip.STL" scale="1 1 1"/>
      </geometry>
      <material name="gold"/>
    </visual>
    <collision>
      <origin rpy="1.57079632679 0 0" xyz="0 0.04 0"/>
      <geometry>
        <cylinder length="0.08" radius="0.041"/>
      </geometry>
    </collision>
    <inertial>
      <origin rpy="0 0 0" xyz="0.001568 0.008134 0.000864"/>
      <mass value="2.354"/>
      <inertia ixx="0.0047303" ixy="2.3798e-05" ixz="4.2348e-08" iyy="0.0051123" iyz="3.807e-06" izz="0.0035171"/>
    </inertial>
  </link>
  <joint name="RR_hip_fixed" type="fixed">
    <origin rpy="0 0 0" xyz="0 -0.04 0"/>
    <parent link="RR_hip"/>
    <child link="RR_thigh_shoulder"/>
  </joint>
  <!-- this link is only for collision -->
  <link name="RR_thigh_shoulder">
    <collision>
      <origin rpy="1.57079632679 0 0" xyz="0 0 0"/>
      <geometry>
        <cylinder length="0.08" radius="0.044"/>
      </geometry>
    </collision>
  </link>
  <joint name="RR_thigh_joint" type="revolute">
    <origin rpy="0 0 0" xyz="-0.1065 -0.062 0"/>
    <parent link="RR_hip"/>
    <child link="RR_thigh"/>
    <axis xyz="0 1 0"/>
    <dynamics damping="0.4" friction="0.2"/>
    <limit effort="550" lower="-3.40025044874" upper="4.300014732279" velocity="28.6"/>
  </joint>
  <link name="RR_thigh">
    <visual>
      <origin rpy="0 0 0" xyz="0 0 0"/>
      <geometry>
        <mesh filename="package://quake_description/meshes/thigh_mirror.STL" scale="1 1 1"/>
      </geometry>
      <material name="gold"/>
    </visual>
    <collision>
      <origin rpy="0 1.57079632679 0" xyz="0 0 -0.18"/>
      <geometry>
        <box size="0.36 0.034 0.043"/>
      </geometry>
    </collision>
    <inertial>
      <origin rpy="0 0 0" xyz="-0.000482 -0.02001 -0.031996"/>
      <mass value="4.199"/>
      <inertia ixx="0.010387" ixy="-2.7648e-05" ixz="-0.0006887" iyy="0.013004" iyz="-0.00021997" izz="0.0029272"/>
    </inertial>
  </link>
  <joint name="RR_calf_joint" type="revolute">
    <origin rpy="0 0 0" xyz="0 -0.062 -0.36"/>
    <parent link="RR_thigh"/>
    <child link="RR_calf"/>
    <axis xyz="0 1 0"/>
    <dynamics damping="0.4" friction="1.0"/>
    <limit effort="550" lower="-2.900007366139" upper="-1.10021361804" velocity="28.6"/>
  </joint>
  <link name="RR_calf">
    <visual>
      <origin rpy="0 0 0" xyz="0 0 0"/>
      <geometry>
        <mesh filename="package://quake_description/meshes/calf.STL" scale="1 1 1"/>
      </geometry>
      <surface>
        <friction>
          <ode>
            <mu>100.0</mu>
            <mu2>100.0</mu2>
          </ode>
        </friction>
      </surface>
      <material name="black"/>
    </visual>
    <collision>
      <origin rpy="0 1.57079632679 0" xyz="0 0 -0.18"/>
      <geometry>
        <box size="0.36 0.016 0.016"/>
      </geometry>
      <surface>
        <friction>
          <ode>
            <mu>100.0</mu>
            <mu2>100.0</mu2>
          </ode>
        </friction>
      </surface>
    </collision>
    <inertial>
      <origin rpy="0 0 0" xyz="-0.002196 -0.000381 -0.12338"/>
      <mass value="0.593"/>
      <inertia ixx="0.0031787" ixy="-1.5425e-07" ixz="0.0002511" iyy="0.0032683" iyz="3.2937e-07" izz="0.0001467"/>
    </inertial>
  </link>
  <joint name="RR_foot_fixed" type="fixed">
    <origin rpy="0 0 0" xyz="0 0 -0.36"/>
    <parent link="RR_calf"/>
    <child link="RR_foot"/>
  </joint>
  <link name="RR_foot">
    <visual>
      <origin rpy="0 0 0" xyz="0 0 0"/>
      <geometry>
        <sphere radius="0.032"/>
      </geometry>
      <surface>
        <friction>
          <ode>
            <mu>100.0</mu>
            <mu2>100.0</mu2>
          </ode>
        </friction>
      </surface>
      <material name="black"/>
    </visual>
    <collision>
      <origin rpy="0 0 0" xyz="0 0 0"/>
      <geometry>
        <sphere radius="0.042"/>
      </geometry>
      <surface>
        <friction>
          <ode>
            <mu>100.0</mu>
            <mu2>100.0</mu2>
          </ode>
        </friction>
        <!-- <contact>
                <min_depth>0.01</min_depth>
                </contact> -->
      </surface>
    </collision>
    <inertial>
      <mass value="0.06"/>
      <inertia ixx="4.2336e-05" ixy="0.0" ixz="0.0" iyy="4.2336e-05" iyz="0.0" izz="4.2336e-05"/>
    </inertial>
  </link>
  <!-- <joint name="${name}_empty_fixed" type="fixed">
            <origin rpy="0 0 0" xyz="0 0 ${-(calf_length)}"/>
            <parent link="${name}_foot"/>
            <child link="${name}_empty"/>
        </joint>

        <link name="${name}_empty">
            <visual>
                <origin rpy="0 0 0" xyz="0 0 0"/>
                <geometry>
                    <sphere radius="0.0001"/>
                </geometry>
                <surface>
                <friction>
                <ode>
                    <mu>100.0</mu>
                    <mu2>100.0</mu2>
                </ode>
                </friction>
                </surface>
                <material name="orange"/>
            </visual>
            <collision>
                <origin rpy="0 0 0" xyz="0 0 0"/>
                <geometry>
                    <sphere radius="0.0001"/>
                </geometry>
                <surface>
                <friction>
                <ode>
                    <mu>100.0</mu>
                    <mu2>100.0</mu2>
                </ode>
                </friction>
                </surface>
            </collision>
            <inertial>
                <mass value="0"/>
                <inertia
                    ixx="0" ixy="0.0" ixz="0.0"
                    iyy="0" iyz="0.0"
                    izz="0"/>             
            </inertial>
        </link> -->
  <gazebo>
    <plugin filename="libgazebo_ros_p3d.so" name="p3d_base_controller">
      <alwaysOn>true</alwaysOn>
      <updateRate>200.0</updateRate>
      <bodyName>RR_calf</bodyName>
      <topicName>ground_truth/state/RR_foot</topicName>
      <gaussianNoise>0.0</gaussianNoise>
      <frameName>world</frameName>
      <xyzOffsets>0 0 0</xyzOffsets>
      <rpyOffsets>0 0 0</rpyOffsets>
    </plugin>
  </gazebo>
  <transmission name="RR_hip_tran">
    <type>transmission_interface/SimpleTransmission</type>
    <joint name="RR_hip_joint">
      <hardwareInterface>hardware_interface/EffortJointInterface</hardwareInterface>
    </joint>
    <actuator name="RR_hip_motor">
      <hardwareInterface>hardware_interface/EffortJointInterface</hardwareInterface>
      <mechanicalReduction>1</mechanicalReduction>
    </actuator>
  </transmission>
  <transmission name="RR_thigh_tran">
    <type>transmission_interface/SimpleTransmission</type>
    <joint name="RR_thigh_joint">
      <hardwareInterface>hardware_interface/EffortJointInterface</hardwareInterface>
    </joint>
    <actuator name="RR_thigh_motor">
      <hardwareInterface>hardware_interface/EffortJointInterface</hardwareInterface>
      <mechanicalReduction>1</mechanicalReduction>
    </actuator>
  </transmission>
  <transmission name="RR_calf_tran">
    <type>transmission_interface/SimpleTransmission</type>
    <joint name="RR_calf_joint">
      <hardwareInterface>hardware_interface/EffortJointInterface</hardwareInterface>
    </joint>
    <actuator name="RR_calf_motor">
      <hardwareInterface>hardware_interface/EffortJointInterface</hardwareInterface>
      <mechanicalReduction>1</mechanicalReduction>
    </actuator>
  </transmission>
  <joint name="RL_hip_joint" type="revolute">
    <origin rpy="0 0 0" xyz="-0.241 0.095 0"/>
    <parent link="trunk"/>
    <child link="RL_hip"/>
    <axis xyz="1 0 0"/>
    <dynamics damping="0.4" friction="0.2"/>
    <limit effort="200" lower="-1.13008323737" upper="1.13008323737" velocity="52.4"/>
  </joint>
  <link name="RL_hip">
    <visual>
      <origin rpy="0 3.14159265359 0" xyz="0 0 0"/>
      <geometry>
        <mesh filename="package://quake_description/meshes/hip.STL" scale="1 1 1"/>
      </geometry>
      <material name="gold"/>
    </visual>
    <collision>
      <origin rpy="1.57079632679 0 0" xyz="0 -0.04 0"/>
      <geometry>
        <cylinder length="0.08" radius="0.041"/>
      </geometry>
    </collision>
    <inertial>
      <origin rpy="0 0 0" xyz="0.001568 -0.008134 0.000864"/>
      <mass value="2.354"/>
      <inertia ixx="0.0047303" ixy="-2.3798e-05" ixz="4.2348e-08" iyy="0.0051123" iyz="-3.807e-06" izz="0.0035171"/>
    </inertial>
  </link>
  <joint name="RL_hip_fixed" type="fixed">
    <origin rpy="0 0 0" xyz="0 0.04 0"/>
    <parent link="RL_hip"/>
    <child link="RL_thigh_shoulder"/>
  </joint>
  <!-- this link is only for collision -->
  <link name="RL_thigh_shoulder">
    <collision>
      <origin rpy="1.57079632679 0 0" xyz="0 0 0"/>
      <geometry>
        <cylinder length="0.08" radius="0.044"/>
      </geometry>
    </collision>
  </link>
  <joint name="RL_thigh_joint" type="revolute">
    <origin rpy="0 0 0" xyz="-0.1065 0.062 0"/>
    <parent link="RL_hip"/>
    <child link="RL_thigh"/>
    <axis xyz="0 1 0"/>
    <dynamics damping="0.4" friction="0.2"/>
    <limit effort="550" lower="-3.40025044874" upper="4.300014732279" velocity="28.6"/>
  </joint>
  <link name="RL_thigh">
    <visual>
      <origin rpy="0 0 0" xyz="0 0 0"/>
      <geometry>
        <mesh filename="package://quake_description/meshes/thigh.STL" scale="1 1 1"/>
      </geometry>
      <material name="gold"/>
    </visual>
    <collision>
      <origin rpy="0 1.57079632679 0" xyz="0 0 -0.18"/>
      <geometry>
        <box size="0.36 0.034 0.043"/>
      </geometry>
    </collision>
    <inertial>
      <origin rpy="0 0 0" xyz="-0.000482 0.02001 -0.031996"/>
      <mass value="4.199"/>
      <inertia ixx="0.010387" ixy="2.7648e-05" ixz="-0.0006887" iyy="0.013004" iyz="0.00021997" izz="0.0029272"/>
    </inertial>
  </link>
  <joint name="RL_calf_joint" type="revolute">
    <origin rpy="0 0 0" xyz="0 0.062 -0.36"/>
    <parent link="RL_thigh"/>
    <child link="RL_calf"/>
    <axis xyz="0 1 0"/>
    <dynamics damping="0.4" friction="1.0"/>
    <limit effort="550" lower="-2.900007366139" upper="-1.10021361804" velocity="28.6"/>
  </joint>
  <link name="RL_calf">
    <visual>
      <origin rpy="0 0 0" xyz="0 0 0"/>
      <geometry>
        <mesh filename="package://quake_description/meshes/calf.STL" scale="1 1 1"/>
      </geometry>
      <surface>
        <friction>
          <ode>
            <mu>100.0</mu>
            <mu2>100.0</mu2>
          </ode>
        </friction>
      </surface>
      <material name="black"/>
    </visual>
    <collision>
      <origin rpy="0 1.57079632679 0" xyz="0 0 -0.18"/>
      <geometry>
        <box size="0.36 0.016 0.016"/>
      </geometry>
      <surface>
        <friction>
          <ode>
            <mu>100.0</mu>
            <mu2>100.0</mu2>
          </ode>
        </friction>
      </surface>
    </collision>
    <inertial>
      <origin rpy="0 0 0" xyz="-0.002196 -0.000381 -0.12338"/>
      <mass value="0.593"/>
      <inertia ixx="0.0031787" ixy="-1.5425e-07" ixz="0.0002511" iyy="0.0032683" iyz="3.2937e-07" izz="0.0001467"/>
    </inertial>
  </link>
  <joint name="RL_foot_fixed" type="fixed">
    <origin rpy="0 0 0" xyz="0 0 -0.36"/>
    <parent link="RL_calf"/>
    <child link="RL_foot"/>
  </joint>
  <link name="RL_foot">
    <visual>
      <origin rpy="0 0 0" xyz="0 0 0"/>
      <geometry>
        <sphere radius="0.032"/>
      </geometry>
      <surface>
        <friction>
          <ode>
            <mu>100.0</mu>
            <mu2>100.0</mu2>
          </ode>
        </friction>
      </surface>
      <material name="black"/>
    </visual>
    <collision>
      <origin rpy="0 0 0" xyz="0 0 0"/>
      <geometry>
        <sphere radius="0.042"/>
      </geometry>
      <surface>
        <friction>
          <ode>
            <mu>100.0</mu>
            <mu2>100.0</mu2>
          </ode>
        </friction>
        <!-- <contact>
                <min_depth>0.01</min_depth>
                </contact> -->
      </surface>
    </collision>
    <inertial>
      <mass value="0.06"/>
      <inertia ixx="4.2336e-05" ixy="0.0" ixz="0.0" iyy="4.2336e-05" iyz="0.0" izz="4.2336e-05"/>
    </inertial>
  </link>
  <!-- <joint name="${name}_empty_fixed" type="fixed">
            <origin rpy="0 0 0" xyz="0 0 ${-(calf_length)}"/>
            <parent link="${name}_foot"/>
            <child link="${name}_empty"/>
        </joint>

        <link name="${name}_empty">
            <visual>
                <origin rpy="0 0 0" xyz="0 0 0"/>
                <geometry>
                    <sphere radius="0.0001"/>
                </geometry>
                <surface>
                <friction>
                <ode>
                    <mu>100.0</mu>
                    <mu2>100.0</mu2>
                </ode>
                </friction>
                </surface>
                <material name="orange"/>
            </visual>
            <collision>
                <origin rpy="0 0 0" xyz="0 0 0"/>
                <geometry>
                    <sphere radius="0.0001"/>
                </geometry>
                <surface>
                <friction>
                <ode>
                    <mu>100.0</mu>
                    <mu2>100.0</mu2>
                </ode>
                </friction>
                </surface>
            </collision>
            <inertial>
                <mass value="0"/>
                <inertia
                    ixx="0" ixy="0.0" ixz="0.0"
                    iyy="0" iyz="0.0"
                    izz="0"/>             
            </inertial>
        </link> -->
  <gazebo>
    <plugin filename="libgazebo_ros_p3d.so" name="p3d_base_controller">
      <alwaysOn>true</alwaysOn>
      <updateRate>200.0</updateRate>
      <bodyName>RL_calf</bodyName>
      <topicName>ground_truth/state/RL_foot</topicName>
      <gaussianNoise>0.0</gaussianNoise>
      <frameName>world</frameName>
      <xyzOffsets>0 0 0</xyzOffsets>
      <rpyOffsets>0 0 0</rpyOffsets>
    </plugin>
  </gazebo>
  <transmission name="RL_hip_tran">
    <type>transmission_interface/SimpleTransmission</type>
    <joint name="RL_hip_joint">
      <hardwareInterface>hardware_interface/EffortJointInterface</hardwareInterface>
    </joint>
    <actuator name="RL_hip_motor">
      <hardwareInterface>hardware_interface/EffortJointInterface</hardwareInterface>
      <mechanicalReduction>1</mechanicalReduction>
    </actuator>
  </transmission>
  <transmission name="RL_thigh_tran">
    <type>transmission_interface/SimpleTransmission</type>
    <joint name="RL_thigh_joint">
      <hardwareInterface>hardware_interface/EffortJointInterface</hardwareInterface>
    </joint>
    <actuator name="RL_thigh_motor">
      <hardwareInterface>hardware_interface/EffortJointInterface</hardwareInterface>
      <mechanicalReduction>1</mechanicalReduction>
    </actuator>
  </transmission>
  <transmission name="RL_calf_tran">
    <type>transmission_interface/SimpleTransmission</type>
    <joint name="RL_calf_joint">
      <hardwareInterface>hardware_interface/EffortJointInterface</hardwareInterface>
    </joint>
    <actuator name="RL_calf_motor">
      <hardwareInterface>hardware_interface/EffortJointInterface</hardwareInterface>
      <mechanicalReduction>1</mechanicalReduction>
    </actuator>
  </transmission>
 
</robot>

